Workbook

Sheet 00_Tổng hợp
A1: MCM — GIỐNG BÒ SỮA MỘC CHÂU · ĐỊNH GIÁ: DCF LÕI + TIỀN + DỰ ÁN, BA KỊCH BẢN (KHÔNG XÁC SUẤT), BỐN PHƯƠNG PHÁP ĐỐI CHIẾU
A2: Bản 15/10/2026 · giá phiên 13/10/2026 · mỗi kịch bản = DCF lõi + (tiền − quỹ) × (1 − k) + dự án · không gán xác suất, giá trị hợp lý = kịch bản cơ sở
A3: Chữ xanh dương nền xanh lá = đầu vào · chữ đen = công thức · chữ xanh lá = lấy từ sheet khác · nền vàng = kết quả · nền cam = cảnh báo. Đơn vị tỷ đồng trừ khi ghi khác.
A5: CHỈ SỐ CHÍNH | B5: Giá thị trường (đồng) | C5: Giá trị cơ sở (đồng) | E5: Biên an toàn
B6: ='01_Số liệu gốc'!$B$11 -> 26600 | C6: =C16 -> 26693.757 | E6: ='03_Định giá'!$B$265 -> 0.0060694119
B7: ="Phiên "&'01_Số liệu gốc'!$B$12 -> Phiên 13/10/2026 | C7: ="DCF + (tiền − quỹ) × "&TEXT((1-'02_Giả định'!$B$26)*100,"0")&"% + dự án" -> DCF + (tiền − quỹ) × 90% + dự án | E7: (cơ sở − giá) ÷ (cơ sở − tiền)
A8: Tự kiểm số học (công thức, tổng, khớp DB) | B8: =IF(AND(OR(LEFT('01_Số liệu gốc'!$D$10,4)="KHỚP",LEFT('01_Số liệu gốc'!$D$10,3)="ĐẠT"),OR(LEFT('01_Số liệu gốc'!$I$36,4)="KHỚP",LEFT('01_Số liệu gốc'!$I$36,3)="ĐẠT"),OR(LEFT('01_Số liệu gốc'!$I$72,4)="KHỚP",LEFT('01_Số liệu gốc'!$I$72,3)="ĐẠT"),OR(LEFT('02_Giả định'!$C$24,4)="KHỚP",LEFT('02_Giả định'!$C$24,3)="ĐẠT"),OR(LEFT('02_Giả định'!$C$45,4)="KHỚP",LEFT('02_Giả định'!$C$45,3)="ĐẠT"),OR(LEFT('03_Định giá'!$H$259,4)="KHỚP",LEFT('03_Định giá'!$H$259,3)="ĐẠT"),OR(LEFT('05_Đối chiếu'!$C$26,4)="KHỚP",LEFT('05_Đối chiếu'!$C$26,3)="ĐẠT"),OR(LEFT('05_Đối chiếu'!$C$27,4)="KHỚP",LEFT('05_Đối chiếu'!$C$27,3)="ĐẠT"),LEFT('06_Dự án'!$G$21,3)="ĐẠT",LEFT('04_Độ nhạy'!$B$65,3)="ĐẠT"),"ĐẠT — 10 phép tự kiểm đều khớp","CÓ PHÉP KIỂM LỆCH — tìm ô báo LỆCH hoặc SAI ở từng sheet") -> ĐẠT — 10 phép tự kiểm đều khớp
A9: 1. KẾT QUẢ CHÍNH (đồng/cổ phiếu)
A10: Phương pháp | B10: Xấu | C10: Cơ sở | D10: Tốt | E10: Trọng số | F10: Ghi chú
A11: 1. P/E lợi nhuận lõi + tiền + dự án | B11: ='03_Định giá'!$B$221 -> 15602.83 | C11: ='03_Định giá'!$C$221 -> 27130.765 | D11: ='03_Định giá'!$D$221 -> 35934.576 | E11: ='02_Giả định'!$B$19 -> 0 | F11: Đối chiếu. Lõi × P/E (02), (tiền − quỹ) × (1 − k), cộng giá trị ròng dự án (06)
A12: 2. DCF phần lõi + tiền + dự án | B12: ='03_Định giá'!$B$239 -> 14575.268 | C12: ='03_Định giá'!$C$239 -> 26693.757 | D12: ='03_Định giá'!$D$239 -> 36657.749 | E12: ='02_Giả định'!$B$20 -> 1 | F12: DÙNG LÀM GIÁ TRỊ. Dòng tiền phần lõi ở r (02 mục A), cộng (tiền − quỹ) × (1 − k) và dự án
A13: 3. Chiết khấu cổ tức (DDM) | B13: ='03_Định giá'!$B$248 -> 8764.0522 | C13: ='03_Định giá'!$C$248 -> 22496.248 | D13: ='03_Định giá'!$D$248 -> 32689.631 | E13: ='02_Giả định'!$B$21 -> 0 | F13: Đối chiếu. Tạm ứng 2026 + cổ tức 2027–2031 theo chính sách, sau đó trả theo ROE
A14: 4. P/B theo ROE | B14: ='03_Định giá'!$B$230 -> 14239.967 | C14: ='03_Định giá'!$C$230 -> 18858.335 | D14: ='03_Định giá'!$D$230 -> 24631.295 | E14: ='02_Giả định'!$B$22 -> 0 | F14: Đối chiếu. ROE lịch sử, không qua động cơ lõi
A15: 5. EV/EBITDA lõi + tiền + dự án | B15: ='03_Định giá'!$B$226 -> 16868.762 | C15: ='03_Định giá'!$C$226 -> 27001.289 | D15: ='03_Định giá'!$D$226 -> 34389.28 | E15: ='02_Giả định'!$B$23 -> 0 | F15: Đối chiếu. EBITDA lõi × bội số (02), cộng (tiền − quỹ) × (1 − k) và dự án
A16: GIÁ TRỊ TỪNG KỊCH BẢN (= phương pháp 2) | B16: ='03_Định giá'!$B$256 -> 14575.268 | C16: ='03_Định giá'!$C$256 -> 26693.757 | D16: ='03_Định giá'!$D$256 -> 36657.749
A17: So giá hiện tại | B17: =B16/'01_Số liệu gốc'!$B$11-1 -> -0.45205758 | C17: =C16/'01_Số liệu gốc'!$B$11-1 -> 0.0035246887 | D17: =D16/'01_Số liệu gốc'!$B$11-1 -> 0.37811087
A18: Phần ngoài tiền (lõi + hai dự án) | B18: ='03_Định giá'!B261 -> 3328.9255 | C18: ='03_Định giá'!C261 -> 15447.414 | D18: ='03_Định giá'!D261 -> 25411.406 | F18: ="Tiền trừ quỹ, sau chiết khấu: "&TEXT('03_Định giá'!$B$260,"#,##0")&" đ/cp — như nhau ở ba kịch bản" -> Tiền trừ quỹ, sau chiết khấu: 11,246 đ/cp — như nhau ở ba kịch bản
A20: Giá thị trường (đồng) | B20: ='01_Số liệu gốc'!$B$11 -> 26600 | F20: ="Phiên "&'01_Số liệu gốc'!$B$12 -> Phiên 13/10/2026
A21: GIÁ TRỊ CƠ SỞ (đồng/cổ phiếu) | B21: ='03_Định giá'!$C$256 -> 26693.757 | F21: Con số trung tâm, không gán xác suất
A22: Biên an toàn trên phần ngoài tiền = (cơ sở − giá) ÷ (cơ sở − tiền) | B22: ='03_Định giá'!$B$265 -> 0.0060694119
A23: Tỷ lệ lên/xuống = (tốt − giá) ÷ (giá − xấu) | B23: ='03_Định giá'!$B$266 -> 0.83642191 | F23: Dưới 1: phần có thể mất lớn hơn phần có thể được
A24: Độ phân tán năm phương pháp (cơ sở, cao ÷ thấp) | B24: ='03_Định giá'!$C$257 -> 1.4386618 | F24: Trên 1,5x: xem vì sao các phương pháp đối chiếu lệch xa DCF
A26: 2. BIỂU ĐỒ — giá trị từng phương pháp (kịch bản cơ sở) so với giá
A46: 3. NHỮNG CON SỐ PHẢI NHỚ TRƯỚC KHI NHÌN MCM
A47: Tiền ròng 30/06/2026 mỗi cổ phiếu (đồng) | B47: ='03_Định giá'!$C$215 -> 12713.973 | C47: Gần một nửa giá cổ phiếu là tiền gửi — câu hỏi là tiền này về cổ đông hay vào dự án · Tính vào giá trị: (tiền − quỹ khen thưởng phúc lợi) × 90%, xem 03 dòng tiền trừ quỹ
A48: Giá trị ròng hai dự án, cơ sở (đồng/cp) | B48: ='03_Định giá'!$C$208 -> -1386.6315 | C48: Âm: phần còn phải chi sinh lời dưới lợi suất dự án — chi tiết 06, giá × chi phí ở 04 bảng 2
A49: Tiền ròng thấp nhất 2027–2031, cơ sở (tỷ) | B49: ='03_Định giá'!$C$199 -> 323.73986 | C49: Cổ tức cơ sở và chi cả hai dự án. Âm = phải vay
A50: Lợi suất yêu cầu phần kinh doanh (r) | B50: ='02_Giả định'!$B$10 -> 0.11224 | C50: Rf 4,6% + β 0,72 × ERP 9,2% (02 mục A)
A51: Lợi suất ngầm định ở giá hiện tại (phần kinh doanh) | B51: ='05_Đối chiếu'!$B$23 -> 0.11633829 | C51: Thấp hơn r = thị trường trả đắt hơn lợi suất yêu cầu (05 mục B)
A52: Lợi suất kỳ vọng cả cổ phiếu nếu mua ở giá hiện tại | B52: ='05_Đối chiếu'!$B$24 -> 0.084821838 | C52: ="So lãi gửi tham chiếu "&TEXT('02_Giả định'!$B$17*100,"0.0")&"% (khoản lớn, thực nhận)" -> So lãi gửi tham chiếu 9.0% (khoản lớn, thực nhận)
A53: LNST Q3/2026 dự báo (tỷ) — mốc kiểm cuối tháng 10 | B53: ='02_Giả định'!$B$56 -> 48.16472 | C53: Ngoài dải ở 05 mục F thì xem lại B và chi phí bán hàng
A55: 4. TIỀN ĐI ĐÂU 2027–2031 — kịch bản cơ sở (tỷ đồng, 03 mục D)
A56: Khoản | B56: 2027 | C56: 2028 | D56: 2029 | E56: 2030 | F56: 2031
A57: Chi dự án | B57: ='03_Định giá'!$C$88 -> 704.679 | C57: ='03_Định giá'!$C$112 -> 355.9615 | D57: ='03_Định giá'!$C$136 -> 355.9615 | E57: ='03_Định giá'!$C$160 -> 0 | F57: ='03_Định giá'!$C$184 -> 0
A58: Cổ tức tiền mặt | B58: ='03_Định giá'!$C$98 -> 165 | C58: ='03_Định giá'!$C$122 -> 165 | D58: ='03_Định giá'!$C$146 -> 165 | E58: ='03_Định giá'!$C$170 -> 165 | F58: ='03_Định giá'!$C$194 -> 165
A59: LNST (cả lãi tiền gửi/vay) | B59: ='03_Định giá'!$C$97 -> 301.42239 | C59: ='03_Định giá'!$C$121 -> 307.49428 | D59: ='03_Định giá'!$C$145 -> 298.71716 | E59: ='03_Định giá'!$C$169 -> 334.60722 | F59: ='03_Định giá'!$C$193 -> 352.9778
A60: TIỀN RÒNG CUỐI NĂM | B60: ='03_Định giá'!$C$100 -> 796.84887 | C60: ='03_Định giá'!$C$124 -> 564.40172 | D60: ='03_Định giá'!$C$148 -> 323.73986 | E60: ='03_Định giá'!$C$172 -> 471.01577 | F60: ='03_Định giá'!$C$196 -> 634.49068
A61: Bắt đầu từ 1.398,5 tỷ ngày 30/06/2026. Cổ tức cơ sở và lãi tiền gửi theo 02 mục C.
A63: 5. CHƯA CÓ SỐ CÔNG BỐ — câu hỏi còn mở ở 06 mục F
A64: 1. Giá bán sữa nguyên liệu cho Vinamilk và giá thu mua nông hộ không công bố — mV 10% là ước của người viết (12/10/2026), giá sữa trang trại là tự đặt.
...

Sheet 01_Số liệu gốc
A1: MCM — SỐ LIỆU GỐC
A2: Mọi số ở đây là DỮ KIỆN (báo cáo tài chính, thuyết minh, BCTN, giá). Nhận định nằm ở 02_Giả định. Nền xanh lá chữ xanh dương = số nhập tay; nền vàng = công thức. Đơn vị tỷ đồng trừ khi ghi khác. Số DB kéo ngày 12/10/2026. MCM không có công ty con: BCTC riêng là BCTC duy nhất. Bảng cân đối 30/06/2026 khớp BCTC bán niên soát xét (KPMG, 11/08/2026).
A4: A. CỔ PHIẾU VÀ GIÁ
A5: Chỉ tiêu | B5: Giá trị | C5: Đơn vị | D5: Nguồn / ghi chú
A6: Cổ phiếu đã phát hành | B6: 110 | C6: triệu cổ phiếu | D6: Thuyết minh 21 BCTC 2025: 110.000.000; không đổi đến 30/06/2026
A7: Cổ phiếu quỹ | B7: 0 | C7: triệu cổ phiếu | D7: BCTC 2025 TM 21: số đang lưu hành = số phát hành
A8: CỔ PHIẾU LƯU HÀNH | B8: =B6-B7 -> 110 | C8: triệu cổ phiếu
A9: Kiểm chéo: vốn góp trong DB (GEN_BS_097) 30/06/2026 | B9: 1100 | C9: tỷ đồng | D9: gen_balance_sheet quý 2/2026
A10: → số cổ phiếu suy từ vốn góp | B10: =B9/10 -> 110 | C10: triệu cổ phiếu | D10: =IF(ABS(B10-B6)<0.001,"KHỚP cổ phiếu đã phát hành","LỆCH") -> KHỚP cổ phiếu đã phát hành
A11: Giá cổ phiếu | B11: 26600 | C11: đồng | D11: daily_price, giá đóng cửa
A12: Ngày giá | B12: 13/10/2026
A13: Cao nhất 52 tuần (giá điều chỉnh cổ tức) | B13: 29400 | C13: đồng | D13: daily_price.adjusted_close
A14: Thấp nhất 52 tuần (giá điều chỉnh cổ tức) | B14: 23744 | C14: đồng | D14: daily_price.adjusted_close
A15: Giá trị giao dịch bình quân 30 phiên | B15: 520.4 | C15: triệu đồng/phiên | D15: daily_price (giá × khối lượng). RẤT THẤP: Vinamilk và Tổng Công ty Chăn nuôi nắm 68,15%
A16: Vốn hoá thị trường | B16: =B11*B8/1000 -> 2926 | C16: tỷ đồng | D16: giá × cổ phiếu lưu hành
A18: B. KẾT QUẢ KINH DOANH THEO NĂM (PostgreSQL, tỷ đồng)
A19: Khoản mục | B19: 2021 | C19: 2022 | D19: 2023 | E19: 2024 | F19: 2025 | I19: Mã khoản mục / ghi chú
A20: Doanh thu thuần | B20: 2925.664 | C20: 3133.099 | D20: 3135.423 | E20: 2916.958 | F20: 2834.874 | I20: GEN_IS_003
A21: Lãi gộp | B21: 898.503 | C21: 1017.789 | D21: 1008.618 | E21: 848.545 | F21: 796.98 | I21: GEN_IS_021
A22: Chi phí bán hàng | B22: 594.259 | C22: 688.742 | D22: 708.879 | E22: 657.046 | F22: 606.614 | I22: GEN_IS_011
A23: Chi phí quản lý doanh nghiệp | B23: 36.609 | C23: 39.603 | D23: 37.898 | E23: 37.145 | F23: 38.071 | I23: GEN_IS_012
A24: LỢI NHUẬN LÕI (EBIT lõi) = lãi gộp − bán hàng − quản lý | B24: =B21-B22-B23 -> 267.635 | C24: =C21-C22-C23 -> 289.444 | D24: =D21-D22-D23 -> 261.841 | E24: =E21-E22-E23 -> 154.354 | F24: =F21-F22-F23 -> 152.295 | I24: Không gồm lãi tiền gửi — phần đó cộng riêng bằng số dư tiền ở mọi phương pháp
A25: Doanh thu hoạt động tài chính (gần hết là lãi tiền gửi) | B25: 95.419 | C25: 103.156 | D25: 162.315 | E25: 101.252 | F25: 103.916 | I25: GEN_IS_004
A26: Chi phí tài chính | B26: 0.5 | C26: 0.996 | D26: 0.881 | E26: 1.898 | F26: 6.004 | I26: GEN_IS_014
A27: trong đó: chi phí lãi vay | B27: 0.163 | C27: 0.636 | D27: 0 | E27: 1.732 | F27: 5.706 | I27: GEN_IS_015
A28: Lợi nhuận khác (thu nhập khác − chi phí khác) | B28: -8.796 | C28: -10.917 | D28: 0.305 | E28: -1.652 | F28: -1.673 | I28: GEN_IS_005−017
A29: Lợi nhuận trước thuế | B29: 353.758 | C29: 380.687 | D29: 423.58 | E29: 252.057 | F29: 248.534 | I29: GEN_IS_027
A30: Thuế thu nhập doanh nghiệp | B30: 34.646 | C30: 34.138 | D30: 49.162 | E30: 32.136 | F30: 32.82 | I30: GEN_IS_006+007
A31: LỢI NHUẬN SAU THUẾ | B31: 319.112 | C31: 346.549 | D31: 374.417 | E31: 219.921 | F31: 215.714 | I31: GEN_IS_020
A32: Khấu hao tài sản cố định | B32: 49.922 | C32: 54.459 | D32: 62.041 | E32: 67.01 | F32: 68.763 | I32: GEN_CF_001
A33: Lưu chuyển tiền thuần từ hoạt động kinh doanh | B33: 230.26 | C33: 268.493 | D33: 287.49 | E33: 196.059 | F33: 180.854 | I33: GEN_CF_026
A34: Chi mua sắm, xây dựng tài sản cố định (âm = tiền ra) | B34: -151.349 | C34: -139.443 | D34: -246.393 | E34: -93.478 | F34: -174.152 | I34: GEN_CF_027
A35: Cổ tức tiền mặt đã trả (âm = tiền ra) | B35: -309.016 | C35: -274.948 | D35: -220.105 | E35: -220 | F35: -220 | I35: GEN_CF_040
A36: Kiểm: lõi + doanh thu tài chính − chi phí tài chính + khác − LNTT | B36: =B24+B25-B26+B28-B29 -> 0 | C36: =C24+C25-C26+C28-C29 -> 0 | D36: =D24+D25-D26+D28-D29 -> 0 | E36: =E24+E25-E26+E28-E29 -> -0.001 | F36: =F24+F25-F26+F28-F29 -> 0 | I36: =IF(MAX(ABS(B36),ABS(C36),ABS(D36),ABS(E36),ABS(F36))<0.5,"KHỚP (dung sai 0,5 tỷ — làm tròn DB)","LỆCH") -> KHỚP (dung sai 0,5 tỷ — làm tròn DB)
A37: Thuế suất thực tế = thuế ÷ lợi nhuận trước thuế | B37: =B30/B29 -> 0.097937008 | C37: =C30/C29 -> 0.08967472 | D37: =D30/D29 -> 0.11606308 | E37: =E30/E29 -> 0.12749497 | F37: =F30/F29 -> 0.13205437 | I37: Thuế suất phổ thông 20%. Thu nhập chăn nuôi, chế biến nông sản ở địa bàn đặc biệt khó khăn được miễn (TM 34 BCTC 2025, Nghị định 320/2025): 2025 miễn 18,0 tỷ tiền thuế
A38: Doanh thu tài chính ÷ lợi nhuận trước thuế | B38: =B25/B29 -> 0.26972959 | C38: =C25/C29 -> 0.27097327 | D38: =D25/D29 -> 0.38319798 | E38: =E25/E29 -> 0.40170279 | F38: =F25/F29 -> 0.41811583 | I38: Lãi tiền gửi từ 27% (2021) lên 42% LNTT (2025): lợi nhuận lõi giảm, tiền gửi đứng yên
A40: C. THEO QUÝ (PostgreSQL, tỷ đồng) — cột H = 12 tháng tới Q2/2026 = năm 2025 kiểm toán − 6T/2025 + 6T/2026
A41: Khoản mục | B41: Q1/2025 | C41: Q2/2025 | D41: Q3/2025 | E41: Q4/2025 | F41: Q1/2026 | G41: Q2/2026 | H41: 12 tháng | I41: Mã khoản mục / ghi chú
A42: Doanh thu thuần | B42: 591.151 | C42: 808.709 | D42: 716.234 | E42: 721.2 | F42: 741.55 | G42: 760.454 | H42: =F20-B42-C42+F42+G42 -> 2937.018 | I42: Từ 2026 áp dụng Thông tư 99: bán bò chuyển từ thu nhập khác sang doanh thu; số cùng kỳ 2025 trong BCTC 2026 đã trình bày lại (lệch DB ~1 tỷ/quý, không đổi LNTT)
A43: Lãi gộp | B43: 145.482 | C43: 236.99 | D43: 202.187 | E43: 209.543 | F43: 212.414 | G43: 235.899 | H43: =F21-B43-C43+F43+G43 -> 862.821 | I43: GEN_IS_021. Cột H lấy năm 2025 kiểm toán làm gốc: cộng thẳng bốn quý 2025 trong DB thiếu 2,8 tỷ lãi gộp so BCTC năm
...

Sheet 02_Giả định
A1: MCM — GIẢ ĐỊNH (bản 15/10/2026: ba kịch bản, không xác suất)
A2: Ô nền xanh lá chữ xanh dương là NHẬN ĐỊNH — sửa là cả model chạy lại. Cột 'Mốc thực tế' lấy thẳng từ 01 để thấy giả định đặt ở đâu so với số thật. Giả định hai dự án nằm ở 06_Dự án.
A4: A. THAM SỐ CHUNG — lợi suất yêu cầu, thuế lãi tiền gửi, trọng số, chiết khấu tiền
A5: Tham số | B5: Giá trị | F5: Căn cứ
A6: Lợi suất phi rủi ro (Rf) | B6: 0.046 | F6: Khung chung của người viết. Trái phiếu Chính phủ 10 năm trúng thầu 4,43% đầu tháng 10/2026 — trong ngưỡng ±0,5 điểm, chưa đổi
A7: Phần bù rủi ro thị trường (ERP) — cách rút gọn của công ty chứng khoán | B7: 0.092 | F7: Chốt 12/10/2026: dùng như VNDirect, VDSC. VNDirect BSR 17/08/2026: 9,2% (Rf 4,3%); VDSC GDA 07/04/2026: 10% (mức cho doanh nghiệp chu kỳ → cận trên, phép thử T5); Kafi PVS 9,63%; MBS VCB 8,5%; KBSV MCM 8% (β 1 → 12%). Damodaran 07/2026 cho Việt Nam 7,92% (4,20% + rủi ro quốc gia 3,72%)
A8: β phần kinh doanh hiện tại (đã bỏ phần tiền) | B8: 0.72 | F8: Chốt 12/10/2026. VNM: Blume 0,644 (thô tuần 5 năm 0,469) ÷ (1 − tiền ròng bình quân 5 năm 11%) = 0,72. MCM tự tính, bỏ tiền TỪNG TUẦN (tiền bình quân 40% vốn hóa): 0,70 (tuần 5 năm, CI 0,50–0,91), 0,76 (tuần 2 năm); Dimson trễ 1 tuần −0,03 → ít giao dịch không làm méo. Phép thử T6 (0,85), T14 (0,65)
A9: β hai dự án mới | B9: 0.85 | F9: TỰ ĐẶT. Dự án làm chi phí cố định tăng (khấu hao trang trại ~40 tỷ + nhà máy ~37 tỷ/năm) và nghiêng hàng cao cấp (Creamery) — nhạy với chu kỳ hơn kinh doanh hiện tại. Rủi ro chậm, kẹt đất KHÔNG đưa vào đây (đã ở kịch bản xấu 06)
A10: LỢI SUẤT YÊU CẦU PHẦN KINH DOANH HIỆN TẠI (r) = Rf + β × ERP | B10: =B6+B8*B7 -> 0.11224 | F10: Không vay nên r cũng là chi phí vốn của DCF.
A11: LỢI SUẤT YÊU CẦU HAI DỰ ÁN = Rf + β dự án × ERP | B11: =B6+B9*B7 -> 0.1242 | F11: Chiết khấu dòng tiền dự án ở 06/03
A12: Tăng trưởng dài hạn (g) | B12: 0.03 | F12: Dùng cho P/B theo ROE, giá trị cuối kỳ DCF và cổ tức. Lạm phát 9T/2026 4,52% — phép thử g 4% không đặt sẵn
A13: Trích quỹ khen thưởng phúc lợi (% LNST) | B13: 0.1 | F13: 2024, 2025 đều đúng 10% (01 mục H). Tiền ra khỏi tay cổ đông trước cổ tức
A14: Thuế trên lãi tiền gửi | B14: 0.2 | F14: Thuế suất phổ thông; phần miễn thuế chỉ áp cho thu nhập chăn nuôi, chế biến nông sản (TM 34 BCTC 2025)
A15: Lãi suất vay khi tiền âm (chỉ dùng ở phương pháp 3) | B15: 0.075 | F15: TỰ ĐẶT. TM 17 BCTC 2025 chỉ ghi vay Vietcombank, VietinBank 4–6 tháng lãi cố định, KHÔNG ghi mức lãi
A16: Cổ tức tạm ứng đợt 1/2026 dự kiến (đồng/cp, khoảng tháng 11/2026) | B16: 1000 | F16: MCM tạm ứng 1.000đ vào tháng 11 các năm 2022–2025; đợt 2026 CHƯA công bố. Cộng vào phương pháp 3
A17: Lãi tiền gửi tham chiếu của nhà đầu tư (khoản lớn, thực nhận) | B17: 0.09 | F17: Niêm yết 6–7,5% (12 tháng, 10/2026); khoản trên 200 triệu thường được cộng thêm 2–2,5% ngoài biểu — không có số công khai. Dùng để so lợi suất kỳ vọng ở 05 mục B
A18: Trọng số phương pháp — Chốt 13/10/2026: chỉ DCF (phương pháp 2) làm giá trị, bốn phương pháp còn lại để đối chiếu (trước: 30/25/20/15/10)
A19: 1. P/E lợi nhuận lõi + tiền + dự án | B19: 0 | F19: Lợi nhuận lõi chuẩn hoá × P/E, cộng tiền theo mệnh giá, cộng giá trị ròng dự án · Từ 13/10/2026 chỉ đối chiếu (trước 30%)
A20: 2. DCF phần lõi + tiền + dự án | B20: 1 | F20: Dòng tiền phần lõi 2027–2031 ở r lõi; hai dự án cộng riêng (06) ở lợi suất dự án · Từ 13/10/2026 DÙNG LÀM GIÁ TRỊ: 100% (trước 25%)
A21: 3. Chiết khấu cổ tức (DDM) | B21: 0 | F21: Cổ đông thiểu số chỉ nhận cổ tức; Vinamilk kiểm soát 68% quyết định chia bao nhiêu · Từ 13/10/2026 chỉ đối chiếu (trước 20%): r phần kinh doanh áp cả lên tiền gửi nên định giá tiền thấp
A22: 4. P/B theo ROE | B22: 0 | F22: ROE lịch sử, độc lập với động cơ lõi; coi tiền gửi nằm lại công ty mãi · Từ 13/10/2026 chỉ đối chiếu (trước 15%): như phương pháp 3, mỗi đồng tiền chỉ được ~0,25 đồng
A23: 5. EV/EBITDA lõi + tiền + dự án | B23: 0 | F23: Gần như trùng phương pháp 1 (không vay) · Từ 13/10/2026 chỉ đối chiếu (trước 10%)
A24: Tổng trọng số (phải bằng 100%) | B24: =SUM(B19:B23) -> 1 | C24: =IF(ABS(B24-1)<0.000001,"ĐẠT","SAI — tổng khác 100%") -> ĐẠT
A26: Chiết khấu tiền ròng khi cộng vào giá trị (k) | B26: 0.1 | F26: Chốt 13/10/2026: giá trị = DCF phần lõi + (tiền ròng − quỹ khen thưởng phúc lợi) × (1 − k) + giá trị ròng dự án. k là phần tiền cổ đông thiểu số có thể không nhận đủ: Vinamilk nắm 68% quyết định chia hay giữ, tiền nằm ở công ty chỉ lãi ~5% sau thuế và quỹ. Mỗi 10 điểm k ≈ 1.250 đ/cp. Áp cho phương pháp 1, 2, 5 (cùng cộng tiền); 04 bảng 4 có k = 0% và 20%. Trừ quỹ từ 14/10/2026: tiền đã trích cho người lao động, không thuộc cổ đông (01 mục D).
A27: B. ĐỘNG CƠ LỢI NHUẬN LÕI — hiệu chỉnh trên 12 tháng tới Q2/2026 (dùng chung PP 1, 2, 3, 5)
A28: Tham số | B28: Giá trị | F28: Cách tính / căn cứ
A29: V 12 tháng = bán cho Vinamilk (2025 − 6T/2025 + 6T/2026) | B29: ='01_Số liệu gốc'!$D$85-'01_Số liệu gốc'!$E$85+'01_Số liệu gốc'!$F$85 -> 637.205 | F29: Thuyết minh bên liên quan, 01 mục E
A30: Doanh thu thuần 12 tháng | B30: ='01_Số liệu gốc'!$H$42 -> 2937.018
A31: B 12 tháng = doanh thu − V | B31: =B30-B29 -> 2299.813 | F31: Thương hiệu + thức ăn chăn nuôi + khác
A32: Lãi gộp 12 tháng | B32: ='01_Số liệu gốc'!$H$43 -> 862.821
A33: Chi phí bán hàng 12 tháng | B33: ='01_Số liệu gốc'!$H$44 -> 629.378
A34: Chi phí quản lý 12 tháng | B34: ='01_Số liệu gốc'!$H$45 -> 37.733
A35: EBIT lõi 12 tháng | B35: ='01_Số liệu gốc'!$H$46 -> 195.71
A36: Hồi quy lãi gộp 2023–2025 theo V và B (không hệ số chặn): biên của V | B36: =INDEX(LINEST('01_Số liệu gốc'!$B$87:$D$87,'01_Số liệu gốc'!$B$85:$D$86,FALSE,FALSE),1,2) -> -0.040691357 | F36: Ra số ÂM — vô lý: hồi quy 3 điểm lẫn cả việc giá thu mua sữa tăng 7–8% năm 2024 (KBSV). Chỉ cho biết biên của V THẤP, không đo được bao nhiêu
A37: Hồi quy như trên: biên của B | B37: =INDEX(LINEST('01_Số liệu gốc'!$B$87:$D$87,'01_Số liệu gốc'!$B$85:$D$86,FALSE,FALSE),1,1) -> 0.37696235
A38: BIÊN GỘP CỦA PHẦN BÁN CHO VINAMILK (mV) DÙNG TRONG MODEL | B38: 0.1 | F38: Ước của người viết (12/10/2026): khoảng 10% (bản trước dùng 5%, xem phép thử T15). Công ty không công bố giá bán cho Vinamilk; BCTC 2025 TM 25–26 chỉ tách thành phẩm/hàng hóa, sữa nguyên liệu nằm trong thành phẩm (biên 29,3%); CSDL gen_notes không có. Chỉ ảnh hưởng khi cơ cấu V/B đổi so 12 tháng (biên B hiệu chỉnh lại theo mV). Độ nhạy: 04 bảng 4 dòng T15 (mV 5%).
A39: Biên gộp của B 12 tháng = (lãi gộp − mV × V) ÷ B | B39: =(B32-B38*B29)/B31 -> 0.34746325
A40: Chi phí bán hàng ÷ B, 12 tháng | B40: =B33/B31 -> 0.27366486
A41: Cùng cách tính các kỳ trước: | B41: 2023 | C41: 2025 | D41: 6T/2025 | E41: 6T/2026
A42: biên gộp của B | B42: =('01_Số liệu gốc'!B87-$B$38*'01_Số liệu gốc'!B85)/'01_Số liệu gốc'!B86 -> 0.35647386 | C42: =('01_Số liệu gốc'!D87-$B$38*'01_Số liệu gốc'!D85)/'01_Số liệu gốc'!D86 -> 0.33698353 | D42: =('01_Số liệu gốc'!E87-$B$38*'01_Số liệu gốc'!E85)/'01_Số liệu gốc'!E86 -> 0.33281576 | E42: =('01_Số liệu gốc'!F87-$B$38*'01_Số liệu gốc'!F85)/'01_Số liệu gốc'!F86 -> 0.35380725
...

Sheet 03_Định giá
A1: MCM — ĐỊNH GIÁ: DCF LÕI + TIỀN + DỰ ÁN (BỐN PHƯƠNG PHÁP ĐỐI CHIẾU), BA KỊCH BẢN, MƯỜI SÁU CỘT PHÉP THỬ (bản 15/10/2026)
A2: Toàn bộ là công thức đọc từ 01 và 02 — không nhập số ở sheet này, TRỪ ô đổi tham số ở cột phép thử (nền xanh lá). Mỗi cột H–W là một bản tính lại đầy đủ: lấy đúng tham số cột Cơ sở, đổi đúng một ô (T15 đổi thêm biên gộp B 12 tháng đi kèm để EBIT 12 tháng vẫn khớp).
H3: Đối chứng: không đổi gì (phải ra đúng cơ sở) | I3: Không xây nhà máy trong 5 năm — MỨC TRẦN (coi nhà máy cũ chạy mãi không tốn thêm) | J3: Nhà máy chạy từ 2028 (lịch công ty: xong Q4/2027) | K3: Sữa trang trại bán thô 13.000 đ/lít | L3: Chi phí nuôi 11.500 đ/lít | M3: ERP 10% (VDSC, cận trên) | N3: β phần kinh doanh 0,85 (bằng dự án) | O3: Cổ tức 1.000đ/cp (tối thiểu 50% LNST) | P3: B về mức 2025 (Creamery không cất cánh) | Q3: B về mức 2023 | R3: Chi phí bán hàng ÷ B = mức 12 tháng | S3: P/E lõi 10x (như bản 09/10) | T3: P/E lõi = P/E trung vị lịch sử MCM | U3: Biên gộp B giữ mức 6T/2026 | V3: β phần kinh doanh 0,65 | W3: Biên gộp bán cho Vinamilk 5% thay cho 10% (cơ sở). Biên gộp B 12 tháng tính lại theo ô này để EBIT 12 tháng vẫn khớp
A4: Chỉ tiêu (tỷ đồng) | B4: Xấu | C4: Cơ sở | D4: Tốt | E4: Trọng số | F4: Cách tính | H4: T0 | I4: T1 | J4: T2 | K4: T3 | L4: T4 | M4: T5 | N4: T6 | O4: T7 | P4: T8 | Q4: T9 | R4: T10 | S4: T11 | T4: T12 | U4: T13 | V4: T14 | W4: T15
A5: P. THAM SỐ — cột Xấu/Cơ sở/Tốt lấy từ 02 và 06; cột phép thử = Cơ sở, trừ một ô nền xanh
A6: B — doanh thu phần còn lại | B6: ='02_Giả định'!B61 -> 2200 | C6: ='02_Giả định'!C61 -> 2450 | D6: ='02_Giả định'!D61 -> 2700 | H6: =$C6 -> 2450 | I6: =$C6 -> 2450 | J6: =$C6 -> 2450 | K6: =$C6 -> 2450 | L6: =$C6 -> 2450 | M6: =$C6 -> 2450 | N6: =$C6 -> 2450 | O6: =$C6 -> 2450 | P6: ='01_Số liệu gốc'!$D$86 -> 2166.786 | Q6: ='01_Số liệu gốc'!$B$86 -> 2710.123 | R6: =$C6 -> 2450 | S6: =$C6 -> 2450 | T6: =$C6 -> 2450 | U6: =$C6 -> 2450 | V6: =$C6 -> 2450 | W6: =$C6 -> 2450
A7: V — bán cho Vinamilk | B7: ='02_Giả định'!B62 -> 700 | C7: ='02_Giả định'!C62 -> 640 | D7: ='02_Giả định'!D62 -> 600 | H7: =$C7 -> 640 | I7: =$C7 -> 640 | J7: =$C7 -> 640 | K7: =$C7 -> 640 | L7: =$C7 -> 640 | M7: =$C7 -> 640 | N7: =$C7 -> 640 | O7: =$C7 -> 640 | ... W7: =$C7 -> 640
A8: Biên gộp B: chênh so 12 tháng | B8: ='02_Giả định'!B63 -> -0.015 | C8: ='02_Giả định'!C63 -> 0 | D8: ='02_Giả định'!D63 -> 0.01 | H8: =$C8 -> 0 | I8: =$C8 -> 0 | J8: =$C8 -> 0 | K8: =$C8 -> 0 | L8: =$C8 -> 0 | M8: =$C8 -> 0 | N8: =$C8 -> 0 | O8: =$C8 -> 0 | ... T8: =$C8 -> 0 | U8: ='02_Giả định'!$E$42-'02_Giả định'!$B$39 -> 0.0063439955 | V8: =$C8 -> 0 | W8: =$C8 -> 0
A9: Chi phí bán hàng ÷ B | B9: ='02_Giả định'!B64 -> 0.28 | C9: ='02_Giả định'!C64 -> 0.27 | D9: ='02_Giả định'!D64 -> 0.26 | H9: =$C9 -> 0.27 | I9: =$C9 -> 0.27 | J9: =$C9 -> 0.27 | K9: =$C9 -> 0.27 | L9: =$C9 -> 0.27 | M9: =$C9 -> 0.27 | N9: =$C9 -> 0.27 | O9: =$C9 -> 0.27 | ... Q9: =$C9 -> 0.27 | R9: ='02_Giả định'!$B$40 -> 0.27366486 | S9: =$C9 -> 0.27 | T9: =$C9 -> 0.27 | U9: =$C9 -> 0.27 | V9: =$C9 -> 0.27 | W9: =$C9 -> 0.27
A10: Thuế suất lõi | B10: ='02_Giả định'!B65 -> 0.09 | C10: ='02_Giả định'!C65 -> 0.09 | D10: ='02_Giả định'!D65 -> 0.09 | H10: =$C10 -> 0.09 | I10: =$C10 -> 0.09 | J10: =$C10 -> 0.09 | K10: =$C10 -> 0.09 | L10: =$C10 -> 0.09 | M10: =$C10 -> 0.09 | N10: =$C10 -> 0.09 | O10: =$C10 -> 0.09 | ... W10: =$C10 -> 0.09
A11: Tăng trưởng B 2027–2031 | B11: ='02_Giả định'!B66 -> 0 | C11: ='02_Giả định'!C66 -> 0.03 | D11: ='02_Giả định'!D66 -> 0.05 | H11: =$C11 -> 0.03 | I11: =$C11 -> 0.03 | J11: =$C11 -> 0.03 | K11: =$C11 -> 0.03 | L11: =$C11 -> 0.03 | M11: =$C11 -> 0.03 | N11: =$C11 -> 0.03 | O11: =$C11 -> 0.03 | ... W11: =$C11 -> 0.03
A12: P/E lõi | B12: ='02_Giả định'!B72 -> 10.8 | C12: ='02_Giả định'!C72 -> 10.8 | D12: ='02_Giả định'!D72 -> 10.8 | H12: =$C12 -> 10.8 | I12: =$C12 -> 10.8 | J12: =$C12 -> 10.8 | K12: =$C12 -> 10.8 | L12: =$C12 -> 10.8 | M12: =$C12 -> 10.8 | N12: =$C12 -> 10.8 | O12: =$C12 -> 10.8 | ... R12: =$C12 -> 10.8 | S12: 10 | T12: ='01_Số liệu gốc'!$B$144 -> 13.89 | U12: =$C12 -> 10.8 | V12: =$C12 -> 10.8 | W12: =$C12 -> 10.8
A13: EV/EBITDA lõi | B13: ='02_Giả định'!B73 -> 6.6 | C13: ='02_Giả định'!C73 -> 6.6 | D13: ='02_Giả định'!D73 -> 6.6 | H13: =$C13 -> 6.6 | I13: =$C13 -> 6.6 | J13: =$C13 -> 6.6 | K13: =$C13 -> 6.6 | L13: =$C13 -> 6.6 | M13: =$C13 -> 6.6 | N13: =$C13 -> 6.6 | O13: =$C13 -> 6.6 | ... W13: =$C13 -> 6.6
A14: ROE chu kỳ | B14: ='02_Giả định'!B75 -> 0.095 | C14: ='02_Giả định'!C75 -> 0.115 | D14: ='02_Giả định'!D75 -> 0.14 | H14: =$C14 -> 0.115 | I14: =$C14 -> 0.115 | J14: =$C14 -> 0.115 | K14: =$C14 -> 0.115 | L14: =$C14 -> 0.115 | M14: =$C14 -> 0.115 | N14: =$C14 -> 0.115 | O14: =$C14 -> 0.115 | ... W14: =$C14 -> 0.115
A15: Cổ tức 2027–2031 (đồng/cp) | B15: ='02_Giả định'!B77 -> 1000 | C15: ='02_Giả định'!C77 -> 1500 | D15: ='02_Giả định'!D77 -> 2000 | H15: =$C15 -> 1500 | I15: =$C15 -> 1500 | J15: =$C15 -> 1500 | K15: =$C15 -> 1500 | L15: =$C15 -> 1500 | M15: =$C15 -> 1500 | N15: =$C15 -> 1500 | O15: 1000 | P15: =$C15 -> 1500 | Q15: =$C15 -> 1500 | R15: =$C15 -> 1500 | S15: =$C15 -> 1500 | T15: =$C15 -> 1500 | U15: =$C15 -> 1500 | V15: =$C15 -> 1500 | W15: =$C15 -> 1500
A16: Lãi suất tiền gửi | B16: ='02_Giả định'!B78 -> 0.065 | C16: ='02_Giả định'!C78 -> 0.07 | D16: ='02_Giả định'!D78 -> 0.075 | H16: =$C16 -> 0.07 | I16: =$C16 -> 0.07 | J16: =$C16 -> 0.07 | K16: =$C16 -> 0.07 | L16: =$C16 -> 0.07 | M16: =$C16 -> 0.07 | N16: =$C16 -> 0.07 | O16: =$C16 -> 0.07 | ... W16: =$C16 -> 0.07
A17: Trang trại: vốn phần bò sữa | B17: ='06_Dự án'!B6 -> 860 | C17: ='06_Dự án'!C6 -> 784 | D17: ='06_Dự án'!D6 -> 784 | H17: =$C17 -> 784 | I17: =$C17 -> 784 | J17: =$C17 -> 784 | K17: =$C17 -> 784 | L17: =$C17 -> 784 | M17: =$C17 -> 784 | N17: =$C17 -> 784 | O17: =$C17 -> 784 | ... W17: =$C17 -> 784
A18: Trang trại: vốn phần du lịch | B18: ='06_Dự án'!B7 -> 336 | C18: ='06_Dự án'!C7 -> 336 | D18: ='06_Dự án'!D7 -> 336 | H18: =$C18 -> 336 | I18: =$C18 -> 336 | J18: =$C18 -> 336 | K18: =$C18 -> 336 | L18: =$C18 -> 336 | M18: =$C18 -> 336 | N18: =$C18 -> 336 | O18: =$C18 -> 336 | ... W18: =$C18 -> 336
A19: Trang trại: triệu lít/năm khi đủ đàn | B19: ='06_Dự án'!B8 -> 18 | C19: ='06_Dự án'!C8 -> 20 | D19: ='06_Dự án'!D8 -> 22 | H19: =$C19 -> 20 | I19: =$C19 -> 20 | J19: =$C19 -> 20 | K19: =$C19 -> 20 | L19: =$C19 -> 20 | M19: =$C19 -> 20 | N19: =$C19 -> 20 | O19: =$C19 -> 20 | ... W19: =$C19 -> 20
A20: Trang trại: sản lượng 2027 | B20: ='06_Dự án'!B9 -> 0.3 | C20: ='06_Dự án'!C9 -> 0.5 | D20: ='06_Dự án'!D9 -> 0.6 | H20: =$C20 -> 0.5 | I20: =$C20 -> 0.5 | J20: =$C20 -> 0.5 | K20: =$C20 -> 0.5 | L20: =$C20 -> 0.5 | M20: =$C20 -> 0.5 | N20: =$C20 -> 0.5 | O20: =$C20 -> 0.5 | ... W20: =$C20 -> 0.5
A21: Trang trại: giá bán (đ/lít) | B21: ='06_Dự án'!B10 -> 13000 | C21: ='06_Dự án'!C10 -> 14500 | D21: ='06_Dự án'!D10 -> 15000 | H21: =$C21 -> 14500 | I21: =$C21 -> 14500 | J21: =$C21 -> 14500 | K21: 13000 | L21: =$C21 -> 14500 | M21: =$C21 -> 14500 | N21: =$C21 -> 14500 | O21: =$C21 -> 14500 | P21: =$C21 -> 14500 | Q21: =$C21 -> 14500 | R21: =$C21 -> 14500 | S21: =$C21 -> 14500 | ... W21: =$C21 -> 14500
A22: Trang trại: chi phí tiền mặt (đ/lít) | B22: ='06_Dự án'!B11 -> 10500 | C22: ='06_Dự án'!C11 -> 10500 | D22: ='06_Dự án'!D11 -> 10500 | H22: =$C22 -> 10500 | I22: =$C22 -> 10500 | J22: =$C22 -> 10500 | K22: =$C22 -> 10500 | L22: 11500 | M22: =$C22 -> 10500 | N22: =$C22 -> 10500 | O22: =$C22 -> 10500 | P22: =$C22 -> 10500 | Q22: =$C22 -> 10500 | R22: =$C22 -> 10500 | S22: =$C22 -> 10500 | T22: =$C22 -> 10500 | ... W22: =$C22 -> 10500
A23: Trang trại: thu thêm bê, bò loại | B23: ='06_Dự án'!B12 -> 0.05 | C23: ='06_Dự án'!C12 -> 0.05 | D23: ='06_Dự án'!D12 -> 0.05 | H23: =$C23 -> 0.05 | I23: =$C23 -> 0.05 | J23: =$C23 -> 0.05 | K23: =$C23 -> 0.05 | L23: =$C23 -> 0.05 | M23: =$C23 -> 0.05 | N23: =$C23 -> 0.05 | O23: =$C23 -> 0.05 | ... W23: =$C23 -> 0.05
A24: Trang trại: chi duy trì | B24: ='06_Dự án'!B13 -> 15 | C24: ='06_Dự án'!C13 -> 15 | D24: ='06_Dự án'!D13 -> 15 | H24: =$C24 -> 15 | I24: =$C24 -> 15 | J24: =$C24 -> 15 | K24: =$C24 -> 15 | L24: =$C24 -> 15 | M24: =$C24 -> 15 | N24: =$C24 -> 15 | O24: =$C24 -> 15 | ... W24: =$C24 -> 15
A25: Trang trại: năm khấu hao | B25: ='06_Dự án'!B14 -> 20 | C25: ='06_Dự án'!C14 -> 20 | D25: ='06_Dự án'!D14 -> 20 | H25: =$C25 -> 20 | I25: =$C25 -> 20 | J25: =$C25 -> 20 | K25: =$C25 -> 20 | L25: =$C25 -> 20 | M25: =$C25 -> 20 | N25: =$C25 -> 20 | O25: =$C25 -> 20 | ... W25: =$C25 -> 20
A26: Du lịch: lãi trước thuế từ 2028 | B26: ='06_Dự án'!B15 -> 0 | C26: ='06_Dự án'!C15 -> 10 | D26: ='06_Dự án'!D15 -> 25 | H26: =$C26 -> 10 | I26: =$C26 -> 10 | J26: =$C26 -> 10 | K26: =$C26 -> 10 | L26: =$C26 -> 10 | M26: =$C26 -> 10 | N26: =$C26 -> 10 | O26: =$C26 -> 10 | ... W26: =$C26 -> 10
A27: Nhà máy: có xây trong 5 năm | B27: ='06_Dự án'!B19 -> 1 | C27: ='06_Dự án'!C19 -> 1 | D27: ='06_Dự án'!D19 -> 1 | H27: =$C27 -> 1 | I27: 0 | J27: =$C27 -> 1 | K27: =$C27 -> 1 | L27: =$C27 -> 1 | M27: =$C27 -> 1 | N27: =$C27 -> 1 | O27: =$C27 -> 1 | P27: =$C27 -> 1 | Q27: =$C27 -> 1 | ... W27: =$C27 -> 1
A28: Nhà máy: vốn giai đoạn 1 | B28: ='06_Dự án'!B20 -> 850 | C28: ='06_Dự án'!C20 -> 743 | D28: ='06_Dự án'!D20 -> 743 | H28: =$C28 -> 743 | I28: =$C28 -> 743 | J28: =$C28 -> 743 | K28: =$C28 -> 743 | L28: =$C28 -> 743 | M28: =$C28 -> 743 | N28: =$C28 -> 743 | O28: =$C28 -> 743 | ... W28: =$C28 -> 743
A29: Nhà máy: năm bắt đầu có lãi | B29: ='06_Dự án'!B21 -> 2032 | C29: ='06_Dự án'!C21 -> 2030 | D29: ='06_Dự án'!D21 -> 2030 | H29: =$C29 -> 2030 | I29: =$C29 -> 2030 | J29: 2028 | K29: =$C29 -> 2030 | L29: =$C29 -> 2030 | M29: =$C29 -> 2030 | N29: =$C29 -> 2030 | O29: =$C29 -> 2030 | P29: =$C29 -> 2030 | Q29: =$C29 -> 2030 | R29: =$C29 -> 2030 | ... W29: =$C29 -> 2030
A30: Nhà máy: lãi tăng thêm sau thuế năm đầu chạy | B30: ='06_Dự án'!B22 -> 20 | C30: ='06_Dự án'!C22 -> 45 | D30: ='06_Dự án'!D22 -> 45 | H30: =$C30 -> 45 | I30: =$C30 -> 45 | J30: =$C30 -> 45 | K30: =$C30 -> 45 | L30: =$C30 -> 45 | M30: =$C30 -> 45 | N30: =$C30 -> 45 | O30: =$C30 -> 45 | ... W30: =$C30 -> 45
A31: Lợi suất phi rủi ro | B31: ='02_Giả định'!$B$6 -> 0.046 | C31: ='02_Giả định'!$B$6 -> 0.046 | D31: ='02_Giả định'!$B$6 -> 0.046 | H31: =$C31 -> 0.046 | I31: =$C31 -> 0.046 | J31: =$C31 -> 0.046 | K31: =$C31 -> 0.046 | L31: =$C31 -> 0.046 | M31: =$C31 -> 0.046 | N31: =$C31 -> 0.046 | O31: =$C31 -> 0.046 | ... W31: =$C31 -> 0.046
A32: Phần bù rủi ro thị trường | B32: ='02_Giả định'!$B$7 -> 0.092 | C32: ='02_Giả định'!$B$7 -> 0.092 | D32: ='02_Giả định'!$B$7 -> 0.092 | H32: =$C32 -> 0.092 | I32: =$C32 -> 0.092 | J32: =$C32 -> 0.092 | K32: =$C32 -> 0.092 | L32: =$C32 -> 0.092 | M32: 0.1 | N32: =$C32 -> 0.092 | O32: =$C32 -> 0.092 | P32: =$C32 -> 0.092 | Q32: =$C32 -> 0.092 | R32: =$C32 -> 0.092 | S32: =$C32 -> 0.092 | T32: =$C32 -> 0.092 | U32: =$C32 -> 0.092 | ... W32: =$C32 -> 0.092
A33: β phần kinh doanh hiện tại | B33: ='02_Giả định'!$B$8 -> 0.72 | C33: ='02_Giả định'!$B$8 -> 0.72 | D33: ='02_Giả định'!$B$8 -> 0.72 | H33: =$C33 -> 0.72 | I33: =$C33 -> 0.72 | J33: =$C33 -> 0.72 | K33: =$C33 -> 0.72 | L33: =$C33 -> 0.72 | M33: =$C33 -> 0.72 | N33: 0.85 | O33: =$C33 -> 0.72 | P33: =$C33 -> 0.72 | Q33: =$C33 -> 0.72 | R33: =$C33 -> 0.72 | S33: =$C33 -> 0.72 | T33: =$C33 -> 0.72 | U33: =$C33 -> 0.72 | V33: 0.65 | W33: =$C33 -> 0.72
A34: β hai dự án | B34: ='02_Giả định'!$B$9 -> 0.85 | C34: ='02_Giả định'!$B$9 -> 0.85 | D34: ='02_Giả định'!$B$9 -> 0.85 | H34: =$C34 -> 0.85 | I34: =$C34 -> 0.85 | J34: =$C34 -> 0.85 | K34: =$C34 -> 0.85 | L34: =$C34 -> 0.85 | M34: =$C34 -> 0.85 | N34: =$C34 -> 0.85 | O34: =$C34 -> 0.85 | ... W34: =$C34 -> 0.85
A35: Tăng trưởng dài hạn g | B35: ='02_Giả định'!$B$12 -> 0.03 | C35: ='02_Giả định'!$B$12 -> 0.03 | D35: ='02_Giả định'!$B$12 -> 0.03 | H35: =$C35 -> 0.03 | I35: =$C35 -> 0.03 | J35: =$C35 -> 0.03 | K35: =$C35 -> 0.03 | L35: =$C35 -> 0.03 | M35: =$C35 -> 0.03 | N35: =$C35 -> 0.03 | O35: =$C35 -> 0.03 | ... W35: =$C35 -> 0.03
A36: Trích quỹ khen thưởng phúc lợi | B36: ='02_Giả định'!$B$13 -> 0.1 | C36: ='02_Giả định'!$B$13 -> 0.1 | D36: ='02_Giả định'!$B$13 -> 0.1 | H36: =$C36 -> 0.1 | I36: =$C36 -> 0.1 | J36: =$C36 -> 0.1 | K36: =$C36 -> 0.1 | L36: =$C36 -> 0.1 | M36: =$C36 -> 0.1 | N36: =$C36 -> 0.1 | O36: =$C36 -> 0.1 | ... W36: =$C36 -> 0.1
A37: Thuế trên lãi tiền gửi | B37: ='02_Giả định'!$B$14 -> 0.2 | C37: ='02_Giả định'!$B$14 -> 0.2 | D37: ='02_Giả định'!$B$14 -> 0.2 | H37: =$C37 -> 0.2 | I37: =$C37 -> 0.2 | J37: =$C37 -> 0.2 | K37: =$C37 -> 0.2 | L37: =$C37 -> 0.2 | M37: =$C37 -> 0.2 | N37: =$C37 -> 0.2 | O37: =$C37 -> 0.2 | ... W37: =$C37 -> 0.2
A38: Lãi suất vay khi tiền âm | B38: ='02_Giả định'!$B$15 -> 0.075 | C38: ='02_Giả định'!$B$15 -> 0.075 | D38: ='02_Giả định'!$B$15 -> 0.075 | H38: =$C38 -> 0.075 | I38: =$C38 -> 0.075 | J38: =$C38 -> 0.075 | K38: =$C38 -> 0.075 | L38: =$C38 -> 0.075 | M38: =$C38 -> 0.075 | N38: =$C38 -> 0.075 | O38: =$C38 -> 0.075 | ... W38: =$C38 -> 0.075
A39: Cổ tức tạm ứng đợt 1/2026 (đồng/cp) | B39: ='02_Giả định'!$B$16 -> 1000 | C39: ='02_Giả định'!$B$16 -> 1000 | D39: ='02_Giả định'!$B$16 -> 1000 | H39: =$C39 -> 1000 | I39: =$C39 -> 1000 | J39: =$C39 -> 1000 | K39: =$C39 -> 1000 | L39: =$C39 -> 1000 | M39: =$C39 -> 1000 | N39: =$C39 -> 1000 | O39: =$C39 -> 1000 | ... W39: =$C39 -> 1000
A40: Biên gộp phần bán cho Vinamilk | B40: ='02_Giả định'!$B$38 -> 0.1 | C40: ='02_Giả định'!$B$38 -> 0.1 | D40: ='02_Giả định'!$B$38 -> 0.1 | H40: =$C40 -> 0.1 | I40: =$C40 -> 0.1 | J40: =$C40 -> 0.1 | K40: =$C40 -> 0.1 | L40: =$C40 -> 0.1 | M40: =$C40 -> 0.1 | N40: =$C40 -> 0.1 | O40: =$C40 -> 0.1 | ... V40: =$C40 -> 0.1 | W40: 0.05
...

Sheet 04_Độ nhạy
A1: MCM — ĐỘ NHẠY (đồng/cổ phiếu)
A2: Quanh kịch bản CƠ SỞ. Ô nền vàng = cơ sở; nền cam = thấp hơn giá hiện tại (bảng 2: âm). Bảng 1–3 là công thức dạng đóng của riêng một phương pháp; bảng 4 đọc từ các cột phép thử ở 03 — mỗi dòng là một bản tính lại đầy đủ cả năm phương pháp. Bảng 5: tổng giá trị ba kịch bản theo chi phí mỗi lít ở trang trại.
A4: BẢNG 1 — RIÊNG PHƯƠNG PHÁP 1: B, doanh thu phần còn lại (hàng, tỷ) × CHI PHÍ BÁN HÀNG ÷ B (cột) — (tiền − quỹ) × (1 − k) như phương pháp 1
A5: hàng \ cột | B5: ='03_Định giá'!$C$9-0.02 -> 0.25 | C5: ='03_Định giá'!$C$9-0.01 -> 0.26 | D5: ='03_Định giá'!$C$9+0 -> 0.27 | E5: ='03_Định giá'!$C$9+0.01 -> 0.28 | F5: ='03_Định giá'!$C$9+0.02 -> 0.29
A6: ='03_Định giá'!$C$6-300 -> 2150 | B6: =MAX(0,(('03_Định giá'!$C$40*'03_Định giá'!$C$7+('03_Định giá'!$C$53-(B$5))*($A6)-'03_Định giá'!$C$42)*(1-'03_Định giá'!$C$10)*(1-'03_Định giá'!$C$36)*'03_Định giá'!$C$12+('03_Định giá'!$C$214-'03_Định giá'!$C$216)*(1-'02_Giả định'!$B$26)+'03_Định giá'!$C$207)*1000/'01_Số liệu gốc'!$B$8) -> 28719.767 | C6: =MAX(0,(('03_Định giá'!$C$40*'03_Định giá'!$C$7+('03_Định giá'!$C$53-(C$5))*($A6)-'03_Định giá'!$C$42)*(1-'03_Định giá'!$C$10)*(1-'03_Định giá'!$C$36)*'03_Định giá'!$C$12+('03_Định giá'!$C$214-'03_Định giá'!$C$216)*(1-'02_Giả định'!$B$26)+'03_Định giá'!$C$207)*1000/'01_Số liệu gốc'!$B$8) -> 26990.933 | D6: =MAX(0,(('03_Định giá'!$C$40*'03_Định giá'!$C$7+('03_Định giá'!$C$53-(D$5))*($A6)-'03_Định giá'!$C$42)*(1-'03_Định giá'!$C$10)*(1-'03_Định giá'!$C$36)*'03_Định giá'!$C$12+('03_Định giá'!$C$214-'03_Định giá'!$C$216)*(1-'02_Giả định'!$B$26)+'03_Định giá'!$C$207)*1000/'01_Số liệu gốc'!$B$8) -> 25262.098 | E6: =MAX(0,(('03_Định giá'!$C$40*'03_Định giá'!$C$7+('03_Định giá'!$C$53-(E$5))*($A6)-'03_Định giá'!$C$42)*(1-'03_Định giá'!$C$10)*(1-'03_Định giá'!$C$36)*'03_Định giá'!$C$12+('03_Định giá'!$C$214-'03_Định giá'!$C$216)*(1-'02_Giả định'!$B$26)+'03_Định giá'!$C$207)*1000/'01_Số liệu gốc'!$B$8) -> 23533.264 | F6: =MAX(0,(('03_Định giá'!$C$40*'03_Định giá'!$C$7+('03_Định giá'!$C$53-(F$5))*($A6)-'03_Định giá'!$C$42)*(1-'03_Định giá'!$C$10)*(1-'03_Định giá'!$C$36)*'03_Định giá'!$C$12+('03_Định giá'!$C$214-'03_Định giá'!$C$216)*(1-'02_Giả định'!$B$26)+'03_Định giá'!$C$207)*1000/'01_Số liệu gốc'!$B$8) -> 21804.429
A7: ='03_Định giá'!$C$6-150 -> 2300 | B7: =MAX(0,(('03_Định giá'!$C$40*'03_Định giá'!$C$7+('03_Định giá'!$C$53-(B$5))*($A7)-'03_Định giá'!$C$42)*(1-'03_Định giá'!$C$10)*(1-'03_Định giá'!$C$36)*'03_Định giá'!$C$12+('03_Định giá'!$C$214-'03_Định giá'!$C$216)*(1-'02_Giả định'!$B$26)+'03_Định giá'!$C$207)*1000/'01_Số liệu gốc'!$B$8) -> 29895.334 | C7: =MAX(0,(('03_Định giá'!$C$40*'03_Định giá'!$C$7+('03_Định giá'!$C$53-(C$5))*($A7)-'03_Định giá'!$C$42)*(1-'03_Định giá'!$C$10)*(1-'03_Định giá'!$C$36)*'03_Định giá'!$C$12+('03_Định giá'!$C$214-'03_Định giá'!$C$216)*(1-'02_Giả định'!$B$26)+'03_Định giá'!$C$207)*1000/'01_Số liệu gốc'!$B$8) -> 28045.883 | D7: =MAX(0,(('03_Định giá'!$C$40*'03_Định giá'!$C$7+('03_Định giá'!$C$53-(D$5))*($A7)-'03_Định giá'!$C$42)*(1-'03_Định giá'!$C$10)*(1-'03_Định giá'!$C$36)*'03_Định giá'!$C$12+('03_Định giá'!$C$214-'03_Định giá'!$C$216)*(1-'02_Giả định'!$B$26)+'03_Định giá'!$C$207)*1000/'01_Số liệu gốc'!$B$8) -> 26196.432 | E7: =MAX(0,(('03_Định giá'!$C$40*'03_Định giá'!$C$7+('03_Định giá'!$C$53-(E$5))*($A7)-'03_Định giá'!$C$42)*(1-'03_Định giá'!$C$10)*(1-'03_Định giá'!$C$36)*'03_Định giá'!$C$12+('03_Định giá'!$C$214-'03_Định giá'!$C$216)*(1-'02_Giả định'!$B$26)+'03_Định giá'!$C$207)*1000/'01_Số liệu gốc'!$B$8) -> 24346.981 | F7: =MAX(0,(('03_Định giá'!$C$40*'03_Định giá'!$C$7+('03_Định giá'!$C$53-(F$5))*($A7)-'03_Định giá'!$C$42)*(1-'03_Định giá'!$C$10)*(1-'03_Định giá'!$C$36)*'03_Định giá'!$C$12+('03_Định giá'!$C$214-'03_Định giá'!$C$216)*(1-'02_Giả định'!$B$26)+'03_Định giá'!$C$207)*1000/'01_Số liệu gốc'!$B$8) -> 22497.53
A8: ='03_Định giá'!$C$6+0 -> 2450 | B8: =MAX(0,(('03_Định giá'!$C$40*'03_Định giá'!$C$7+('03_Định giá'!$C$53-(B$5))*($A8)-'03_Định giá'!$C$42)*(1-'03_Định giá'!$C$10)*(1-'03_Định giá'!$C$36)*'03_Định giá'!$C$12+('03_Định giá'!$C$214-'03_Định giá'!$C$216)*(1-'02_Giả định'!$B$26)+'03_Định giá'!$C$207)*1000/'01_Số liệu gốc'!$B$8) -> 31070.9 | C8: =MAX(0,(('03_Định giá'!$C$40*'03_Định giá'!$C$7+('03_Định giá'!$C$53-(C$5))*($A8)-'03_Định giá'!$C$42)*(1-'03_Định giá'!$C$10)*(1-'03_Định giá'!$C$36)*'03_Định giá'!$C$12+('03_Định giá'!$C$214-'03_Định giá'!$C$216)*(1-'02_Giả định'!$B$26)+'03_Định giá'!$C$207)*1000/'01_Số liệu gốc'!$B$8) -> 29100.833 | D8: =MAX(0,(('03_Định giá'!$C$40*'03_Định giá'!$C$7+('03_Định giá'!$C$53-(D$5))*($A8)-'03_Định giá'!$C$42)*(1-'03_Định giá'!$C$10)*(1-'03_Định giá'!$C$36)*'03_Định giá'!$C$12+('03_Định giá'!$C$214-'03_Định giá'!$C$216)*(1-'02_Giả định'!$B$26)+'03_Định giá'!$C$207)*1000/'01_Số liệu gốc'!$B$8) -> 27130.765 | E8: =MAX(0,(('03_Định giá'!$C$40*'03_Định giá'!$C$7+('03_Định giá'!$C$53-(E$5))*($A8)-'03_Định giá'!$C$42)*(1-'03_Định giá'!$C$10)*(1-'03_Định giá'!$C$36)*'03_Định giá'!$C$12+('03_Định giá'!$C$214-'03_Định giá'!$C$216)*(1-'02_Giả định'!$B$26)+'03_Định giá'!$C$207)*1000/'01_Số liệu gốc'!$B$8) -> 25160.698 | F8: =MAX(0,(('03_Định giá'!$C$40*'03_Định giá'!$C$7+('03_Định giá'!$C$53-(F$5))*($A8)-'03_Định giá'!$C$42)*(1-'03_Định giá'!$C$10)*(1-'03_Định giá'!$C$36)*'03_Định giá'!$C$12+('03_Định giá'!$C$214-'03_Định giá'!$C$216)*(1-'02_Giả định'!$B$26)+'03_Định giá'!$C$207)*1000/'01_Số liệu gốc'!$B$8) -> 23190.631
A9: ='03_Định giá'!$C$6+150 -> 2600 | B9: =MAX(0,(('03_Định giá'!$C$40*'03_Định giá'!$C$7+('03_Định giá'!$C$53-(B$5))*($A9)-'03_Định giá'!$C$42)*(1-'03_Định giá'!$C$10)*(1-'03_Định giá'!$C$36)*'03_Định giá'!$C$12+('03_Định giá'!$C$214-'03_Định giá'!$C$216)*(1-'02_Giả định'!$B$26)+'03_Định giá'!$C$207)*1000/'01_Số liệu gốc'!$B$8) -> 32246.466 | C9: =MAX(0,(('03_Định giá'!$C$40*'03_Định giá'!$C$7+('03_Định giá'!$C$53-(C$5))*($A9)-'03_Định giá'!$C$42)*(1-'03_Định giá'!$C$10)*(1-'03_Định giá'!$C$36)*'03_Định giá'!$C$12+('03_Định giá'!$C$214-'03_Định giá'!$C$216)*(1-'02_Giả định'!$B$26)+'03_Định giá'!$C$207)*1000/'01_Số liệu gốc'!$B$8) -> 30155.783 | D9: =MAX(0,(('03_Định giá'!$C$40*'03_Định giá'!$C$7+('03_Định giá'!$C$53-(D$5))*($A9)-'03_Định giá'!$C$42)*(1-'03_Định giá'!$C$10)*(1-'03_Định giá'!$C$36)*'03_Định giá'!$C$12+('03_Định giá'!$C$214-'03_Định giá'!$C$216)*(1-'02_Giả định'!$B$26)+'03_Định giá'!$C$207)*1000/'01_Số liệu gốc'!$B$8) -> 28065.099 | E9: =MAX(0,(('03_Định giá'!$C$40*'03_Định giá'!$C$7+('03_Định giá'!$C$53-(E$5))*($A9)-'03_Định giá'!$C$42)*(1-'03_Định giá'!$C$10)*(1-'03_Định giá'!$C$36)*'03_Định giá'!$C$12+('03_Định giá'!$C$214-'03_Định giá'!$C$216)*(1-'02_Giả định'!$B$26)+'03_Định giá'!$C$207)*1000/'01_Số liệu gốc'!$B$8) -> 25974.415 | F9: =MAX(0,(('03_Định giá'!$C$40*'03_Định giá'!$C$7+('03_Định giá'!$C$53-(F$5))*($A9)-'03_Định giá'!$C$42)*(1-'03_Định giá'!$C$10)*(1-'03_Định giá'!$C$36)*'03_Định giá'!$C$12+('03_Định giá'!$C$214-'03_Định giá'!$C$216)*(1-'02_Giả định'!$B$26)+'03_Định giá'!$C$207)*1000/'01_Số liệu gốc'!$B$8) -> 23883.732
A10: ='03_Định giá'!$C$6+300 -> 2750 | B10: =MAX(0,(('03_Định giá'!$C$40*'03_Định giá'!$C$7+('03_Định giá'!$C$53-(B$5))*($A10)-'03_Định giá'!$C$42)*(1-'03_Định giá'!$C$10)*(1-'03_Định giá'!$C$36)*'03_Định giá'!$C$12+('03_Định giá'!$C$214-'03_Định giá'!$C$216)*(1-'02_Giả định'!$B$26)+'03_Định giá'!$C$207)*1000/'01_Số liệu gốc'!$B$8) -> 33422.032 | C10: =MAX(0,(('03_Định giá'!$C$40*'03_Định giá'!$C$7+('03_Định giá'!$C$53-(C$5))*($A10)-'03_Định giá'!$C$42)*(1-'03_Định giá'!$C$10)*(1-'03_Định giá'!$C$36)*'03_Định giá'!$C$12+('03_Định giá'!$C$214-'03_Định giá'!$C$216)*(1-'02_Giả định'!$B$26)+'03_Định giá'!$C$207)*1000/'01_Số liệu gốc'!$B$8) -> 31210.732 | D10: =MAX(0,(('03_Định giá'!$C$40*'03_Định giá'!$C$7+('03_Định giá'!$C$53-(D$5))*($A10)-'03_Định giá'!$C$42)*(1-'03_Định giá'!$C$10)*(1-'03_Định giá'!$C$36)*'03_Định giá'!$C$12+('03_Định giá'!$C$214-'03_Định giá'!$C$216)*(1-'02_Giả định'!$B$26)+'03_Định giá'!$C$207)*1000/'01_Số liệu gốc'!$B$8) -> 28999.432 | E10: =MAX(0,(('03_Định giá'!$C$40*'03_Định giá'!$C$7+('03_Định giá'!$C$53-(E$5))*($A10)-'03_Định giá'!$C$42)*(1-'03_Định giá'!$C$10)*(1-'03_Định giá'!$C$36)*'03_Định giá'!$C$12+('03_Định giá'!$C$214-'03_Định giá'!$C$216)*(1-'02_Giả định'!$B$26)+'03_Định giá'!$C$207)*1000/'01_Số liệu gốc'!$B$8) -> 26788.132 | F10: =MAX(0,(('03_Định giá'!$C$40*'03_Định giá'!$C$7+('03_Định giá'!$C$53-(F$5))*($A10)-'03_Định giá'!$C$42)*(1-'03_Định giá'!$C$10)*(1-'03_Định giá'!$C$36)*'03_Định giá'!$C$12+('03_Định giá'!$C$214-'03_Định giá'!$C$216)*(1-'02_Giả định'!$B$26)+'03_Định giá'!$C$207)*1000/'01_Số liệu gốc'!$B$8) -> 24576.832
A11: Mỗi 1 điểm % chi phí bán hàng trên ~2.450 tỷ doanh thu = ~24,5 tỷ EBIT — gần bằng 150 tỷ doanh thu. Khuyến mãi quyết định lợi nhuận nhiều như doanh thu.
A13: BẢNG 2 — GIÁ TRỊ RÒNG HAI DỰ ÁN (đồng/cp): GIÁ BÁN SỮA TRANG TRẠI (hàng, đ/lít) × CHI PHÍ TIỀN MẶT MỖI LÍT (cột)
A14: hàng \ cột | B14: ='03_Định giá'!$C$22-1000 -> 9500 | C14: ='03_Định giá'!$C$22-500 -> 10000 | D14: ='03_Định giá'!$C$22+0 -> 10500 | E14: ='03_Định giá'!$C$22+500 -> 11000 | F14: ='03_Định giá'!$C$22+1000 -> 11500
A15: ='03_Định giá'!$C$21-2000 -> 12500 | B15: =('03_Định giá'!$C$207+'03_Định giá'!$C$19*((($A15)-'03_Định giá'!$C$21)*(1+'03_Định giá'!$C$23)-((B$14)-'03_Định giá'!$C$22))/1000*'03_Định giá'!$C$209)*1000/'01_Số liệu gốc'!$B$8 -> -2678.2143 | C15: =('03_Định giá'!$C$207+'03_Định giá'!$C$19*((($A15)-'03_Định giá'!$C$21)*(1+'03_Định giá'!$C$23)-((C$14)-'03_Định giá'!$C$22))/1000*'03_Định giá'!$C$209)*1000/'01_Số liệu gốc'!$B$8 -> -3265.2974 | D15: =('03_Định giá'!$C$207+'03_Định giá'!$C$19*((($A15)-'03_Định giá'!$C$21)*(1+'03_Định giá'!$C$23)-((D$14)-'03_Định giá'!$C$22))/1000*'03_Định giá'!$C$209)*1000/'01_Số liệu gốc'!$B$8 -> -3852.3804 | E15: =('03_Định giá'!$C$207+'03_Định giá'!$C$19*((($A15)-'03_Định giá'!$C$21)*(1+'03_Định giá'!$C$23)-((E$14)-'03_Định giá'!$C$22))/1000*'03_Định giá'!$C$209)*1000/'01_Số liệu gốc'!$B$8 -> -4439.4635 | F15: =('03_Định giá'!$C$207+'03_Định giá'!$C$19*((($A15)-'03_Định giá'!$C$21)*(1+'03_Định giá'!$C$23)-((F$14)-'03_Định giá'!$C$22))/1000*'03_Định giá'!$C$209)*1000/'01_Số liệu gốc'!$B$8 -> -5026.5466
A16: ='03_Định giá'!$C$21-1000 -> 13500 | B16: =('03_Định giá'!$C$207+'03_Định giá'!$C$19*((($A16)-'03_Định giá'!$C$21)*(1+'03_Định giá'!$C$23)-((B$14)-'03_Định giá'!$C$22))/1000*'03_Định giá'!$C$209)*1000/'01_Số liệu gốc'!$B$8 -> -1445.3398 | C16: =('03_Định giá'!$C$207+'03_Định giá'!$C$19*((($A16)-'03_Định giá'!$C$21)*(1+'03_Định giá'!$C$23)-((C$14)-'03_Định giá'!$C$22))/1000*'03_Định giá'!$C$209)*1000/'01_Số liệu gốc'!$B$8 -> -2032.4229 | D16: =('03_Định giá'!$C$207+'03_Định giá'!$C$19*((($A16)-'03_Định giá'!$C$21)*(1+'03_Định giá'!$C$23)-((D$14)-'03_Định giá'!$C$22))/1000*'03_Định giá'!$C$209)*1000/'01_Số liệu gốc'!$B$8 -> -2619.506 | E16: =('03_Định giá'!$C$207+'03_Định giá'!$C$19*((($A16)-'03_Định giá'!$C$21)*(1+'03_Định giá'!$C$23)-((E$14)-'03_Định giá'!$C$22))/1000*'03_Định giá'!$C$209)*1000/'01_Số liệu gốc'!$B$8 -> -3206.589 | F16: =('03_Định giá'!$C$207+'03_Định giá'!$C$19*((($A16)-'03_Định giá'!$C$21)*(1+'03_Định giá'!$C$23)-((F$14)-'03_Định giá'!$C$22))/1000*'03_Định giá'!$C$209)*1000/'01_Số liệu gốc'!$B$8 -> -3793.6721
A17: ='03_Định giá'!$C$21+0 -> 14500 | B17: =('03_Định giá'!$C$207+'03_Định giá'!$C$19*((($A17)-'03_Định giá'!$C$21)*(1+'03_Định giá'!$C$23)-((B$14)-'03_Định giá'!$C$22))/1000*'03_Định giá'!$C$209)*1000/'01_Số liệu gốc'!$B$8 -> -212.46541 | C17: =('03_Định giá'!$C$207+'03_Định giá'!$C$19*((($A17)-'03_Định giá'!$C$21)*(1+'03_Định giá'!$C$23)-((C$14)-'03_Định giá'!$C$22))/1000*'03_Định giá'!$C$209)*1000/'01_Số liệu gốc'!$B$8 -> -799.54847 | D17: =('03_Định giá'!$C$207+'03_Định giá'!$C$19*((($A17)-'03_Định giá'!$C$21)*(1+'03_Định giá'!$C$23)-((D$14)-'03_Định giá'!$C$22))/1000*'03_Định giá'!$C$209)*1000/'01_Số liệu gốc'!$B$8 -> -1386.6315 | E17: =('03_Định giá'!$C$207+'03_Định giá'!$C$19*((($A17)-'03_Định giá'!$C$21)*(1+'03_Định giá'!$C$23)-((E$14)-'03_Định giá'!$C$22))/1000*'03_Định giá'!$C$209)*1000/'01_Số liệu gốc'!$B$8 -> -1973.7146 | F17: =('03_Định giá'!$C$207+'03_Định giá'!$C$19*((($A17)-'03_Định giá'!$C$21)*(1+'03_Định giá'!$C$23)-((F$14)-'03_Định giá'!$C$22))/1000*'03_Định giá'!$C$209)*1000/'01_Số liệu gốc'!$B$8 -> -2560.7977
A18: ='03_Định giá'!$C$21+1000 -> 15500 | B18: =('03_Định giá'!$C$207+'03_Định giá'!$C$19*((($A18)-'03_Định giá'!$C$21)*(1+'03_Định giá'!$C$23)-((B$14)-'03_Định giá'!$C$22))/1000*'03_Định giá'!$C$209)*1000/'01_Số liệu gốc'!$B$8 -> 1020.409 | C18: =('03_Định giá'!$C$207+'03_Định giá'!$C$19*((($A18)-'03_Định giá'!$C$21)*(1+'03_Định giá'!$C$23)-((C$14)-'03_Định giá'!$C$22))/1000*'03_Định giá'!$C$209)*1000/'01_Số liệu gốc'!$B$8 -> 433.32597 | D18: =('03_Định giá'!$C$207+'03_Định giá'!$C$19*((($A18)-'03_Định giá'!$C$21)*(1+'03_Định giá'!$C$23)-((D$14)-'03_Định giá'!$C$22))/1000*'03_Định giá'!$C$209)*1000/'01_Số liệu gốc'!$B$8 -> -153.7571 | E18: =('03_Định giá'!$C$207+'03_Định giá'!$C$19*((($A18)-'03_Định giá'!$C$21)*(1+'03_Định giá'!$C$23)-((E$14)-'03_Định giá'!$C$22))/1000*'03_Định giá'!$C$209)*1000/'01_Số liệu gốc'!$B$8 -> -740.84017 | F18: =('03_Định giá'!$C$207+'03_Định giá'!$C$19*((($A18)-'03_Định giá'!$C$21)*(1+'03_Định giá'!$C$23)-((F$14)-'03_Định giá'!$C$22))/1000*'03_Định giá'!$C$209)*1000/'01_Số liệu gốc'!$B$8 -> -1327.9232
A19: ='03_Định giá'!$C$21+2000 -> 16500 | B19: =('03_Định giá'!$C$207+'03_Định giá'!$C$19*((($A19)-'03_Định giá'!$C$21)*(1+'03_Định giá'!$C$23)-((B$14)-'03_Định giá'!$C$22))/1000*'03_Định giá'!$C$209)*1000/'01_Số liệu gốc'!$B$8 -> 2253.2835 | C19: =('03_Định giá'!$C$207+'03_Định giá'!$C$19*((($A19)-'03_Định giá'!$C$21)*(1+'03_Định giá'!$C$23)-((C$14)-'03_Định giá'!$C$22))/1000*'03_Định giá'!$C$209)*1000/'01_Số liệu gốc'!$B$8 -> 1666.2004 | D19: =('03_Định giá'!$C$207+'03_Định giá'!$C$19*((($A19)-'03_Định giá'!$C$21)*(1+'03_Định giá'!$C$23)-((D$14)-'03_Định giá'!$C$22))/1000*'03_Định giá'!$C$209)*1000/'01_Số liệu gốc'!$B$8 -> 1079.1173 | E19: =('03_Định giá'!$C$207+'03_Định giá'!$C$19*((($A19)-'03_Định giá'!$C$21)*(1+'03_Định giá'!$C$23)-((E$14)-'03_Định giá'!$C$22))/1000*'03_Định giá'!$C$209)*1000/'01_Số liệu gốc'!$B$8 -> 492.03428 | F19: =('03_Định giá'!$C$207+'03_Định giá'!$C$19*((($A19)-'03_Định giá'!$C$21)*(1+'03_Định giá'!$C$23)-((F$14)-'03_Định giá'!$C$22))/1000*'03_Định giá'!$C$209)*1000/'01_Số liệu gốc'!$B$8 -> -95.048792
A20: Nhà máy giữ nguyên cơ sở. Mỗi 1.000 đ/lít ≈ 20 tỷ lãi trước khấu hao/năm. Cộng thẳng vào cả năm phương pháp (trừ P/B theo ROE). Mức hòa vốn từng kịch bản ở 06 mục C.
A22: BẢNG 3 — RIÊNG PHƯƠNG PHÁP 4: ROE CHU KỲ (hàng) × LỢI SUẤT YÊU CẦU r (cột)
A23: hàng \ cột | B23: ='03_Định giá'!$C$44-0.02 -> 0.09224 | C23: ='03_Định giá'!$C$44-0.01 -> 0.10224 | D23: ='03_Định giá'!$C$44+0 -> 0.11224 | E23: ='03_Định giá'!$C$44+0.01 -> 0.12224 | F23: ='03_Định giá'!$C$44+0.02 -> 0.13224
A24: ='03_Định giá'!$C$14-0.03 -> 0.085 | B24: =MAX(0,(($A24)*(1-'03_Định giá'!$C$36)-'03_Định giá'!$C$35)/((B$23)-'03_Định giá'!$C$35)*'01_Số liệu gốc'!$C$74) -> 15764.583 | C24: =MAX(0,(($A24)*(1-'03_Định giá'!$C$36)-'03_Định giá'!$C$35)/((C$23)-'03_Định giá'!$C$35)*'01_Số liệu gốc'!$C$74) -> 13582.331 | D24: =MAX(0,(($A24)*(1-'03_Định giá'!$C$36)-'03_Định giá'!$C$35)/((D$23)-'03_Định giá'!$C$35)*'01_Số liệu gốc'!$C$74) -> 11930.783 | E24: =MAX(0,(($A24)*(1-'03_Định giá'!$C$36)-'03_Định giá'!$C$35)/((E$23)-'03_Định giá'!$C$35)*'01_Số liệu gốc'!$C$74) -> 10637.333 | F24: =MAX(0,(($A24)*(1-'03_Định giá'!$C$36)-'03_Định giá'!$C$35)/((F$23)-'03_Định giá'!$C$35)*'01_Số liệu gốc'!$C$74) -> 9596.9055
A25: ='03_Định giá'!$C$14-0.015 -> 0.1 | B25: =MAX(0,(($A25)*(1-'03_Định giá'!$C$36)-'03_Định giá'!$C$35)/((B$23)-'03_Định giá'!$C$35)*'01_Số liệu gốc'!$C$74) -> 20341.397 | C25: =MAX(0,(($A25)*(1-'03_Định giá'!$C$36)-'03_Định giá'!$C$35)/((C$23)-'03_Định giá'!$C$35)*'01_Số liệu gốc'!$C$74) -> 17525.589 | D25: =MAX(0,(($A25)*(1-'03_Định giá'!$C$36)-'03_Định giá'!$C$35)/((D$23)-'03_Định giá'!$C$35)*'01_Số liệu gốc'!$C$74) -> 15394.559 | E25: =MAX(0,(($A25)*(1-'03_Định giá'!$C$36)-'03_Định giá'!$C$35)/((E$23)-'03_Định giá'!$C$35)*'01_Số liệu gốc'!$C$74) -> 13725.591 | F25: =MAX(0,(($A25)*(1-'03_Định giá'!$C$36)-'03_Định giá'!$C$35)/((F$23)-'03_Định giá'!$C$35)*'01_Số liệu gốc'!$C$74) -> 12383.104
A26: ='03_Định giá'!$C$14+0 -> 0.115 | B26: =MAX(0,(($A26)*(1-'03_Định giá'!$C$36)-'03_Định giá'!$C$35)/((B$23)-'03_Định giá'!$C$35)*'01_Số liệu gốc'!$C$74) -> 24918.211 | C26: =MAX(0,(($A26)*(1-'03_Định giá'!$C$36)-'03_Định giá'!$C$35)/((C$23)-'03_Định giá'!$C$35)*'01_Số liệu gốc'!$C$74) -> 21468.846 | D26: =MAX(0,(($A26)*(1-'03_Định giá'!$C$36)-'03_Định giá'!$C$35)/((D$23)-'03_Định giá'!$C$35)*'01_Số liệu gốc'!$C$74) -> 18858.335 | E26: =MAX(0,(($A26)*(1-'03_Định giá'!$C$36)-'03_Định giá'!$C$35)/((E$23)-'03_Định giá'!$C$35)*'01_Số liệu gốc'!$C$74) -> 16813.849 | F26: =MAX(0,(($A26)*(1-'03_Định giá'!$C$36)-'03_Định giá'!$C$35)/((F$23)-'03_Định giá'!$C$35)*'01_Số liệu gốc'!$C$74) -> 15169.302
A27: ='03_Định giá'!$C$14+0.015 -> 0.13 | B27: =MAX(0,(($A27)*(1-'03_Định giá'!$C$36)-'03_Định giá'!$C$35)/((B$23)-'03_Định giá'!$C$35)*'01_Số liệu gốc'!$C$74) -> 29495.026 | C27: =MAX(0,(($A27)*(1-'03_Định giá'!$C$36)-'03_Định giá'!$C$35)/((C$23)-'03_Định giá'!$C$35)*'01_Số liệu gốc'!$C$74) -> 25412.104 | D27: =MAX(0,(($A27)*(1-'03_Định giá'!$C$36)-'03_Định giá'!$C$35)/((D$23)-'03_Định giá'!$C$35)*'01_Số liệu gốc'!$C$74) -> 22322.111 | E27: =MAX(0,(($A27)*(1-'03_Định giá'!$C$36)-'03_Định giá'!$C$35)/((E$23)-'03_Định giá'!$C$35)*'01_Số liệu gốc'!$C$74) -> 19902.107 | F27: =MAX(0,(($A27)*(1-'03_Định giá'!$C$36)-'03_Định giá'!$C$35)/((F$23)-'03_Định giá'!$C$35)*'01_Số liệu gốc'!$C$74) -> 17955.501
A28: ='03_Định giá'!$C$14+0.03 -> 0.145 | B28: =MAX(0,(($A28)*(1-'03_Định giá'!$C$36)-'03_Định giá'!$C$35)/((B$23)-'03_Định giá'!$C$35)*'01_Số liệu gốc'!$C$74) -> 34071.84 | C28: =MAX(0,(($A28)*(1-'03_Định giá'!$C$36)-'03_Định giá'!$C$35)/((C$23)-'03_Định giá'!$C$35)*'01_Số liệu gốc'!$C$74) -> 29355.361 | D28: =MAX(0,(($A28)*(1-'03_Định giá'!$C$36)-'03_Định giá'!$C$35)/((D$23)-'03_Định giá'!$C$35)*'01_Số liệu gốc'!$C$74) -> 25785.887 | E28: =MAX(0,(($A28)*(1-'03_Định giá'!$C$36)-'03_Định giá'!$C$35)/((E$23)-'03_Định giá'!$C$35)*'01_Số liệu gốc'!$C$74) -> 22990.365 | F28: =MAX(0,(($A28)*(1-'03_Định giá'!$C$36)-'03_Định giá'!$C$35)/((F$23)-'03_Định giá'!$C$35)*'01_Số liệu gốc'!$C$74) -> 20741.699
A29: r ± 1 điểm ≈ β ± 0,11 ở ERP 9,2%. Phép thử β 0,65 / 0,85 và ERP 10% tính đủ cả năm phương pháp ở bảng 4 (T5, T6, T14).
A31: BẢNG 4 — PHÉP THỬ MỘT BIẾN trên GIÁ TRỊ CƠ SỞ = DCF + (tiền − quỹ) × (1 − k) + dự án (tính lại đầy đủ ở 03 cột H–W)
A32: Phép thử | B32: Giá trị thử | C32: Giá trị cơ sở | D32: Chênh (đồng) | E32: Chênh % | F32: Cột ở 03 | G32: Đọc thế nào
A33: T0 · Đối chứng: không đổi gì (phải ra đúng cơ sở) | C33: ='03_Định giá'!$H$256 -> 26693.757 | D33: =C33-'03_Định giá'!$C$256 -> 0 | E33: =C33/'03_Định giá'!$C$256-1 -> 0 | F33: H | G33: Phải bằng 0 — kiểm đường ống phép thử
A34: T1 · Không xây nhà máy trong 5 năm — MỨC TRẦN (coi nhà máy cũ chạy mãi không tốn thêm) | B34: ='03_Định giá'!$I$27 -> 0 | C34: ='03_Định giá'!$I$256 -> 27647.686 | D34: =C34-'03_Định giá'!$C$256 -> 953.92891 | E34: =C34/'03_Định giá'!$C$256-1 -> 0.035736031 | F34: I | G34: MỨC TRẦN: không tính chi phí giữ nhà máy cũ (hết đất, xuống cấp) hay Creamery bị chặn công suất
A35: T2 · Nhà máy chạy từ 2028 (lịch công ty: xong Q4/2027) | B35: ='03_Định giá'!$J$29 -> 2028 | C35: ='03_Định giá'!$J$256 -> 26513.158 | D35: =C35-'03_Định giá'!$C$256 -> -180.59873 | E35: =C35/'03_Định giá'!$C$256-1 -> -0.0067655793 | F35: J | G35: Chi sớm hơn nhưng có lãi sớm hơn
A36: T3 · Sữa trang trại bán thô 13.000 đ/lít | B36: ='03_Định giá'!$K$21 -> 13000 | C36: ='03_Định giá'!$K$256 -> 24844.445 | D36: =C36-'03_Định giá'!$C$256 -> -1849.3117 | E36: =C36/'03_Định giá'!$C$256-1 -> -0.069278809 | F36: K | G36: Creamery không hút được sữa trại mới — bán thô cho Vinamilk
A37: T4 · Chi phí nuôi 11.500 đ/lít | B37: ='03_Định giá'!$L$22 -> 11500 | C37: ='03_Định giá'!$L$256 -> 25519.591 | D37: =C37-'03_Định giá'!$C$256 -> -1174.1661 | E37: =C37/'03_Định giá'!$C$256-1 -> -0.043986545 | F37: L
A38: T5 · ERP 10% (VDSC, cận trên) | B38: ='03_Định giá'!$M$32 -> 0.1 | C38: ='03_Định giá'!$M$256 -> 25186.558 | D38: =C38-'03_Định giá'!$C$256 -> -1507.1982 | E38: =C38/'03_Định giá'!$C$256-1 -> -0.056462575 | F38: M | G38: Mức VDSC dùng cho doanh nghiệp chu kỳ
A39: T6 · β phần kinh doanh 0,85 (bằng dự án) | B39: ='03_Định giá'!$N$33 -> 0.85 | C39: ='03_Định giá'!$N$256 -> 24720.972 | D39: =C39-'03_Định giá'!$C$256 -> -1972.7848 | E39: =C39/'03_Định giá'!$C$256-1 -> -0.073904353 | F39: N | G39: Coi kinh doanh hiện tại rủi ro như dự án
A40: T7 · Cổ tức 1.000đ/cp (tối thiểu 50% LNST) | B40: ='03_Định giá'!$O$15 -> 1000 | C40: ='03_Định giá'!$O$256 -> 26693.757 | D40: =C40-'03_Định giá'!$C$256 -> 0 | E40: =C40/'03_Định giá'!$C$256-1 -> 0 | F40: O | G40: Ít tiền về cổ đông sớm, ít phải vay · Từ 13/10/2026 chênh 0: chỉ đổi phương pháp đối chiếu
A41: T8 · B về mức 2025 (Creamery không cất cánh) | B41: ='03_Định giá'!$P$6 -> 2166.786 | C41: ='03_Định giá'!$P$256 -> 25015.838 | D41: =C41-'03_Định giá'!$C$256 -> -1677.9188 | E41: =C41/'03_Định giá'!$C$256-1 -> -0.0628581 | F41: P | G41: Creamery không bù được sữa thương hiệu đang giảm
A42: T9 · B về mức 2023 | B42: ='03_Định giá'!$Q$6 -> 2710.123 | C42: ='03_Định giá'!$Q$256 -> 28234.871 | D42: =C42-'03_Định giá'!$C$256 -> 1541.1148 | E42: =C42/'03_Định giá'!$C$256-1 -> 0.057733154 | F42: Q | G42: Hàng thương hiệu trở lại thời trước 2024
A43: T10 · Chi phí bán hàng ÷ B = mức 12 tháng | B43: ='03_Định giá'!$R$9 -> 0.27366486 | C43: ='03_Định giá'!$R$256 -> 25950.278 | D43: =C43-'03_Định giá'!$C$256 -> -743.47888 | E43: =C43/'03_Định giá'!$C$256-1 -> -0.027852163 | F43: R
A44: T11 · P/E lõi 10x (như bản 09/10) | B44: ='03_Định giá'!$S$12 -> 10 | C44: ='03_Định giá'!$S$256 -> 26693.757 | D44: =C44-'03_Định giá'!$C$256 -> 0 | E44: =C44/'03_Định giá'!$C$256-1 -> 0 | F44: S | G44: Bội số bản 09/10 (khi r = 14%) · Từ 13/10/2026 chênh 0: chỉ đổi phương pháp đối chiếu
...

Sheet 05_Đối chiếu
A1: MCM — ĐỐI CHIẾU CHÉO
A3: A. BỘI SỐ TẠI GIÁ THỊ TRƯỜNG VÀ TẠI GIÁ TRỊ CƠ SỞ
A4: Chỉ tiêu | B4: Tại giá thị trường | D4: Tại giá trị cơ sở | F4: Ghi chú
A5: Vốn hoá (tỷ đồng) | B5: ='01_Số liệu gốc'!$B$11*'01_Số liệu gốc'!$B$8/1000 -> 2926 | D5: ='03_Định giá'!$C$256*'01_Số liệu gốc'!$B$8/1000 -> 2936.3132
A6: Giá trị phần lõi + dự án = vốn hoá − tiền ròng (tỷ đồng) | B6: =B5-'01_Số liệu gốc'!$C$65 -> 1527.463 | D6: =D5-'01_Số liệu gốc'!$C$65 -> 1537.7762 | F6: Thị trường trả cho kinh doanh lõi CỘNG hai dự án bao nhiêu sau khi trừ tiền
A7: P/E 12 tháng (cả lãi tiền gửi) | B7: =B5/'01_Số liệu gốc'!$H$51 -> 11.218035 | D7: =D5/'01_Số liệu gốc'!$H$51 -> 11.257575 | F7: Cách thị trường và Vietcap đọc
A8: P/E lõi 12 tháng = (vốn hoá − tiền) ÷ lợi nhuận lõi sau thuế, sau quỹ | B8: =B6/('02_Giả định'!$B$35*(1-'02_Giả định'!$B$48)*(1-'02_Giả định'!$B$13)) -> 9.3651204 | D8: =D6/('02_Giả định'!$B$35*(1-'02_Giả định'!$B$48)*(1-'02_Giả định'!$B$13)) -> 9.4283526 | F8: Coi dự án hòa vốn
A9: P/E lõi chuẩn hoá cơ sở | B9: =B6/'03_Định giá'!$C$58 -> 8.6832624 | D9: =D6/'03_Định giá'!$C$58 -> 8.7418907 | F9: So P/E đặt ở 02 (10,8x) — chưa trừ giá trị ròng dự án
A10: P/B (sổ sách 30/06/2026) | B10: ='01_Số liệu gốc'!$B$11/'01_Số liệu gốc'!$C$74 -> 1.2606152 | D10: ='03_Định giá'!$C$256/'01_Số liệu gốc'!$C$74 -> 1.2650584
A11: EV/EBITDA lõi 12 tháng (EV = vốn hoá − tiền) | B11: =B6/('02_Giả định'!$B$35+'01_Số liệu gốc'!$H$52) -> 5.7472035 | D11: =D6/('02_Giả định'!$B$35+'01_Số liệu gốc'!$H$52) -> 5.7860079
A12: Tỷ suất cổ tức (2.000đ/cp như 2022–2025) | B12: ='01_Số liệu gốc'!$B$135/'01_Số liệu gốc'!$B$11 -> 0.07518797 | D12: ='01_Số liệu gốc'!$B$135/'03_Định giá'!$C$256 -> 0.074923887 | F12: Cổ tức 2025 cao hơn LNST sau quỹ — chính sách 2026 hạ về tối thiểu 50% LNST
A13: P/E lõi cơ bản = (1 − quỹ − g ÷ ROIC) ÷ ((1 − quỹ) × (r − g)), ROIC trạng thái dừng (02 mục B) | B13: =(1-'02_Giả định'!$B$13-'02_Giả định'!$B$12/'02_Giả định'!$B$54)/((1-'02_Giả định'!$B$13)*('02_Giả định'!$B$10-'02_Giả định'!$B$12)) -> 9.7892537 | F13: Bội số mà ROIC lõi và r (02 mục A) biện minh được. Đặt ở 02: 10,8x
A14: EV/EBITDA lõi cơ bản = (1 − thuế)(1 − quỹ − g ÷ ROIC) × EBIT/EBITDA ÷ (r − g), ROIC trạng thái dừng (02 mục B) | B14: =(1-'02_Giả định'!$B$48)*(1-'02_Giả định'!$B$13-'02_Giả định'!$B$12/'02_Giả định'!$B$54)*('02_Giả định'!$B$35/('02_Giả định'!$B$35+'01_Số liệu gốc'!$H$52))/('02_Giả định'!$B$10-'02_Giả định'!$B$12) -> 6.0074863 | F14: Đặt ở 02: 6,6x
A16: B. GIÁ ĐANG NGẦM ĐỊNH ĐIỀU GÌ — giải ngược dạng đóng
A17: (a) ROE thuộc cổ đông ngầm định (công thức phương pháp 4) | B17: ='02_Giả định'!$B$12+'01_Số liệu gốc'!$B$11/'01_Số liệu gốc'!$C$74*('02_Giả định'!$B$10-'02_Giả định'!$B$12) -> 0.13367299
A18: quy về ROE trước trích quỹ | B18: =B17/(1-'02_Giả định'!$B$13) -> 0.14852555 | F18: So ROE 2022–2025 bình quân và 12 tháng (01 mục F)
A19: (b) P/E lõi ngầm định nếu hai dự án hòa vốn | B19: =(('01_Số liệu gốc'!$B$11*'01_Số liệu gốc'!$B$8/1000)-'01_Số liệu gốc'!$C$65)/'03_Định giá'!$C$58 -> 8.6832624 | F19: Trên lợi nhuận lõi chuẩn hoá cơ sở
A20: (c) P/E lõi ngầm định với giá trị ròng dự án cơ sở | B20: =(('01_Số liệu gốc'!$B$11*'01_Số liệu gốc'!$B$8/1000)-'01_Số liệu gốc'!$C$65-'03_Định giá'!$C$207)/'03_Định giá'!$C$58 -> 9.550356 | F20: Cao hơn P/E đặt ở 02 nghĩa là giá đang trả trước cho dự án tốt hơn cơ sở
A21: (d) B (doanh thu phần còn lại) ngầm định ở P/E đặt ở 02 và dự án cơ sở (tỷ) | B21: =((('01_Số liệu gốc'!$B$11*'01_Số liệu gốc'!$B$8/1000)-'01_Số liệu gốc'!$C$65-'03_Định giá'!$C$207)/'03_Định giá'!$C$12/((1-'03_Định giá'!$C$10)*(1-'03_Định giá'!$C$36))+'03_Định giá'!$C$42-'03_Định giá'!$C$40*'03_Định giá'!$C$7)/('03_Định giá'!$C$53-'03_Định giá'!$C$9) -> 2129.1731 | F21: So B cơ sở 2.450; 12 tháng 2.302; đỉnh 2023 2.710
A22: (e) Giá trị ròng dự án ngầm định ở P/E đặt ở 02 và lõi cơ sở (tỷ) | B22: =('01_Số liệu gốc'!$B$11*'01_Số liệu gốc'!$B$8/1000)-'01_Số liệu gốc'!$C$65-'03_Định giá'!$C$219 -> -372.35296 | F22: So giá trị ròng dự án cơ sở ở 06 mục C
